[2024-05-27T13:22:22.113+0000] {local_task_job_runner.py:120} INFO - ::group::Pre task execution logs
[2024-05-27T13:22:22.132+0000] {taskinstance.py:2076} INFO - Dependencies all met for dep_context=non-requeueable deps ti=<TaskInstance: dag_with_postgres_operator_v03.create_postgres_table manual__2024-05-27T13:17:19.599154+00:00 [queued]>
[2024-05-27T13:22:22.138+0000] {taskinstance.py:2076} INFO - Dependencies all met for dep_context=requeueable deps ti=<TaskInstance: dag_with_postgres_operator_v03.create_postgres_table manual__2024-05-27T13:17:19.599154+00:00 [queued]>
[2024-05-27T13:22:22.139+0000] {taskinstance.py:2306} INFO - Starting attempt 2 of 6
[2024-05-27T13:22:22.152+0000] {taskinstance.py:2330} INFO - Executing <Task(PostgresOperator): create_postgres_table> on 2024-05-27 13:17:19.599154+00:00
[2024-05-27T13:22:22.158+0000] {warnings.py:110} WARNING - /home/***/.local/lib/python3.12/site-packages/***/task/task_runner/standard_task_runner.py:61: DeprecationWarning: This process (pid=204) is multi-threaded, use of fork() may lead to deadlocks in the child.
  pid = os.fork()

[2024-05-27T13:22:22.159+0000] {standard_task_runner.py:90} INFO - Running: ['***', 'tasks', 'run', 'dag_with_postgres_operator_v03', 'create_postgres_table', 'manual__2024-05-27T13:17:19.599154+00:00', '--job-id', '107', '--raw', '--subdir', 'DAGS_FOLDER/dag_with_postgres_operator.py', '--cfg-path', '/tmp/tmp5eq0en7t']
[2024-05-27T13:22:22.160+0000] {standard_task_runner.py:63} INFO - Started process 206 to run task
[2024-05-27T13:22:22.160+0000] {standard_task_runner.py:91} INFO - Job 107: Subtask create_postgres_table
[2024-05-27T13:22:22.196+0000] {task_command.py:426} INFO - Running <TaskInstance: dag_with_postgres_operator_v03.create_postgres_table manual__2024-05-27T13:17:19.599154+00:00 [running]> on host 2f91d40c74f3
[2024-05-27T13:22:22.258+0000] {taskinstance.py:2648} INFO - Exporting env vars: AIRFLOW_CTX_DAG_OWNER='test' AIRFLOW_CTX_DAG_ID='dag_with_postgres_operator_v03' AIRFLOW_CTX_TASK_ID='create_postgres_table' AIRFLOW_CTX_EXECUTION_DATE='2024-05-27T13:17:19.599154+00:00' AIRFLOW_CTX_TRY_NUMBER='2' AIRFLOW_CTX_DAG_RUN_ID='manual__2024-05-27T13:17:19.599154+00:00'
[2024-05-27T13:22:22.259+0000] {taskinstance.py:430} INFO - ::endgroup::
[2024-05-27T13:22:22.268+0000] {sql.py:276} INFO - Executing: 
            create table if not exists dag_runs (
                dt date,
                dag_id character varying,
                primary key (dt, dag_id)
            )
        
[2024-05-27T13:22:22.276+0000] {base.py:84} INFO - Using connection ID 'postgres_localhost' for task execution.
[2024-05-27T13:22:22.283+0000] {base.py:84} INFO - Using connection ID 'postgres_localhost' for task execution.
[2024-05-27T13:22:22.288+0000] {taskinstance.py:441} INFO - ::group::Post task execution logs
[2024-05-27T13:22:22.288+0000] {taskinstance.py:2905} ERROR - Task failed with exception
Traceback (most recent call last):
  File "/home/airflow/.local/lib/python3.12/site-packages/airflow/models/taskinstance.py", line 465, in _execute_task
    result = _execute_callable(context=context, **execute_callable_kwargs)
             ^^^^^^^^^^^^^^^^^^^^^^^^^^^^^^^^^^^^^^^^^^^^^^^^^^^^^^^^^^^^^
  File "/home/airflow/.local/lib/python3.12/site-packages/airflow/models/taskinstance.py", line 432, in _execute_callable
    return execute_callable(context=context, **execute_callable_kwargs)
           ^^^^^^^^^^^^^^^^^^^^^^^^^^^^^^^^^^^^^^^^^^^^^^^^^^^^^^^^^^^^
  File "/home/airflow/.local/lib/python3.12/site-packages/airflow/models/baseoperator.py", line 400, in wrapper
    return func(self, *args, **kwargs)
           ^^^^^^^^^^^^^^^^^^^^^^^^^^^
  File "/home/airflow/.local/lib/python3.12/site-packages/airflow/providers/common/sql/operators/sql.py", line 282, in execute
    output = hook.run(
             ^^^^^^^^^
  File "/home/airflow/.local/lib/python3.12/site-packages/airflow/providers/common/sql/hooks/sql.py", line 411, in run
    with closing(self.get_conn()) as conn:
                 ^^^^^^^^^^^^^^^
  File "/home/airflow/.local/lib/python3.12/site-packages/airflow/providers/postgres/hooks/postgres.py", line 161, in get_conn
    self.conn = psycopg2.connect(**conn_args)
                ^^^^^^^^^^^^^^^^^^^^^^^^^^^^^
  File "/home/airflow/.local/lib/python3.12/site-packages/psycopg2/__init__.py", line 122, in connect
    conn = _connect(dsn, connection_factory=connection_factory, **kwasync)
           ^^^^^^^^^^^^^^^^^^^^^^^^^^^^^^^^^^^^^^^^^^^^^^^^^^^^^^^^^^^^^^^
psycopg2.OperationalError: could not translate host name "host.docker.local" to address: Name or service not known

[2024-05-27T13:22:22.296+0000] {taskinstance.py:1206} INFO - Marking task as UP_FOR_RETRY. dag_id=dag_with_postgres_operator_v03, task_id=create_postgres_table, run_id=manual__2024-05-27T13:17:19.599154+00:00, execution_date=20240527T131719, start_date=20240527T132222, end_date=20240527T132222
[2024-05-27T13:22:22.308+0000] {standard_task_runner.py:110} ERROR - Failed to execute job 107 for task create_postgres_table (could not translate host name "host.docker.local" to address: Name or service not known
; 206)
[2024-05-27T13:22:22.334+0000] {local_task_job_runner.py:240} INFO - Task exited with return code 1
[2024-05-27T13:22:22.347+0000] {taskinstance.py:3498} INFO - 0 downstream tasks scheduled from follow-on schedule check
[2024-05-27T13:22:22.351+0000] {local_task_job_runner.py:222} INFO - ::endgroup::
