[2024-05-27T16:34:59.248+0000] {local_task_job_runner.py:120} INFO - ::group::Pre task execution logs
[2024-05-27T16:34:59.268+0000] {taskinstance.py:2076} INFO - Dependencies all met for dep_context=non-requeueable deps ti=<TaskInstance: get_data_from_pss.fetch_and_store_data manual__2024-05-27T16:34:57.731012+00:00 [queued]>
[2024-05-27T16:34:59.275+0000] {taskinstance.py:2076} INFO - Dependencies all met for dep_context=requeueable deps ti=<TaskInstance: get_data_from_pss.fetch_and_store_data manual__2024-05-27T16:34:57.731012+00:00 [queued]>
[2024-05-27T16:34:59.276+0000] {taskinstance.py:2306} INFO - Starting attempt 1 of 6
[2024-05-27T16:34:59.288+0000] {taskinstance.py:2330} INFO - Executing <Task(PythonOperator): fetch_and_store_data> on 2024-05-27 16:34:57.731012+00:00
[2024-05-27T16:34:59.294+0000] {warnings.py:110} WARNING - /home/***/.local/lib/python3.12/site-packages/***/task/task_runner/standard_task_runner.py:61: DeprecationWarning: This process (pid=307) is multi-threaded, use of fork() may lead to deadlocks in the child.
  pid = os.fork()

[2024-05-27T16:34:59.295+0000] {standard_task_runner.py:63} INFO - Started process 308 to run task
[2024-05-27T16:34:59.295+0000] {standard_task_runner.py:90} INFO - Running: ['***', 'tasks', 'run', 'get_data_from_pss', 'fetch_and_store_data', 'manual__2024-05-27T16:34:57.731012+00:00', '--job-id', '169', '--raw', '--subdir', 'DAGS_FOLDER/extract_datafrom_pss.py', '--cfg-path', '/tmp/tmpezj16zmq']
[2024-05-27T16:34:59.297+0000] {standard_task_runner.py:91} INFO - Job 169: Subtask fetch_and_store_data
[2024-05-27T16:34:59.335+0000] {task_command.py:426} INFO - Running <TaskInstance: get_data_from_pss.fetch_and_store_data manual__2024-05-27T16:34:57.731012+00:00 [running]> on host a2673611c42c
[2024-05-27T16:34:59.402+0000] {taskinstance.py:2648} INFO - Exporting env vars: AIRFLOW_CTX_DAG_OWNER='***' AIRFLOW_CTX_DAG_ID='get_data_from_pss' AIRFLOW_CTX_TASK_ID='fetch_and_store_data' AIRFLOW_CTX_EXECUTION_DATE='2024-05-27T16:34:57.731012+00:00' AIRFLOW_CTX_TRY_NUMBER='1' AIRFLOW_CTX_DAG_RUN_ID='manual__2024-05-27T16:34:57.731012+00:00'
[2024-05-27T16:34:59.403+0000] {taskinstance.py:430} INFO - ::endgroup::
[2024-05-27T16:34:59.433+0000] {taskinstance.py:441} INFO - ::group::Post task execution logs
[2024-05-27T16:34:59.434+0000] {taskinstance.py:2905} ERROR - Task failed with exception
Traceback (most recent call last):
  File "/home/airflow/.local/lib/python3.12/site-packages/airflow/models/taskinstance.py", line 465, in _execute_task
    result = _execute_callable(context=context, **execute_callable_kwargs)
             ^^^^^^^^^^^^^^^^^^^^^^^^^^^^^^^^^^^^^^^^^^^^^^^^^^^^^^^^^^^^^
  File "/home/airflow/.local/lib/python3.12/site-packages/airflow/models/taskinstance.py", line 432, in _execute_callable
    return execute_callable(context=context, **execute_callable_kwargs)
           ^^^^^^^^^^^^^^^^^^^^^^^^^^^^^^^^^^^^^^^^^^^^^^^^^^^^^^^^^^^^
  File "/home/airflow/.local/lib/python3.12/site-packages/airflow/models/baseoperator.py", line 400, in wrapper
    return func(self, *args, **kwargs)
           ^^^^^^^^^^^^^^^^^^^^^^^^^^^
  File "/home/airflow/.local/lib/python3.12/site-packages/airflow/operators/python.py", line 235, in execute
    return_value = self.execute_callable()
                   ^^^^^^^^^^^^^^^^^^^^^^^
  File "/home/airflow/.local/lib/python3.12/site-packages/airflow/operators/python.py", line 252, in execute_callable
    return self.python_callable(*self.op_args, **self.op_kwargs)
           ^^^^^^^^^^^^^^^^^^^^^^^^^^^^^^^^^^^^^^^^^^^^^^^^^^^^^
  File "/opt/airflow/dags/extract_datafrom_pss.py", line 20, in get_data_from_pss
    with open("C:/Users/simo_/Desktop/test.csv"):
         ^^^^^^^^^^^^^^^^^^^^^^^^^^^^^^^^^^^^^^^
FileNotFoundError: [Errno 2] No such file or directory: 'C:/Users/simo_/Desktop/test.csv'
[2024-05-27T16:34:59.448+0000] {taskinstance.py:1206} INFO - Marking task as UP_FOR_RETRY. dag_id=get_data_from_pss, task_id=fetch_and_store_data, run_id=manual__2024-05-27T16:34:57.731012+00:00, execution_date=20240527T163457, start_date=20240527T163459, end_date=20240527T163459
[2024-05-27T16:34:59.458+0000] {standard_task_runner.py:110} ERROR - Failed to execute job 169 for task fetch_and_store_data ([Errno 2] No such file or directory: 'C:/Users/simo_/Desktop/test.csv'; 308)
[2024-05-27T16:34:59.470+0000] {local_task_job_runner.py:240} INFO - Task exited with return code 1
[2024-05-27T16:34:59.481+0000] {taskinstance.py:3498} INFO - 0 downstream tasks scheduled from follow-on schedule check
[2024-05-27T16:34:59.485+0000] {local_task_job_runner.py:222} INFO - ::endgroup::
