[2024-05-27T13:10:27.554+0000] {local_task_job_runner.py:120} INFO - ::group::Pre task execution logs
[2024-05-27T13:10:27.598+0000] {taskinstance.py:2076} INFO - Dependencies all met for dep_context=non-requeueable deps ti=<TaskInstance: dag_with_postgres_operator_v03.create_postgres_table scheduled__2021-12-26T00:00:00+00:00 [queued]>
[2024-05-27T13:10:27.612+0000] {taskinstance.py:2076} INFO - Dependencies all met for dep_context=requeueable deps ti=<TaskInstance: dag_with_postgres_operator_v03.create_postgres_table scheduled__2021-12-26T00:00:00+00:00 [queued]>
[2024-05-27T13:10:27.613+0000] {taskinstance.py:2306} INFO - Starting attempt 3 of 6
[2024-05-27T13:10:27.635+0000] {taskinstance.py:2330} INFO - Executing <Task(PostgresOperator): create_postgres_table> on 2021-12-26 00:00:00+00:00
[2024-05-27T13:10:27.643+0000] {warnings.py:110} WARNING - /home/***/.local/lib/python3.12/site-packages/***/task/task_runner/standard_task_runner.py:61: DeprecationWarning: This process (pid=236) is multi-threaded, use of fork() may lead to deadlocks in the child.
  pid = os.fork()

[2024-05-27T13:10:27.644+0000] {standard_task_runner.py:90} INFO - Running: ['***', 'tasks', 'run', 'dag_with_postgres_operator_v03', 'create_postgres_table', 'scheduled__2021-12-26T00:00:00+00:00', '--job-id', '72', '--raw', '--subdir', 'DAGS_FOLDER/dag_with_postgres_operator.py', '--cfg-path', '/tmp/tmpk6_3et7w']
[2024-05-27T13:10:27.645+0000] {standard_task_runner.py:63} INFO - Started process 252 to run task
[2024-05-27T13:10:27.646+0000] {standard_task_runner.py:91} INFO - Job 72: Subtask create_postgres_table
[2024-05-27T13:10:27.700+0000] {task_command.py:426} INFO - Running <TaskInstance: dag_with_postgres_operator_v03.create_postgres_table scheduled__2021-12-26T00:00:00+00:00 [running]> on host bce46d08f6f0
[2024-05-27T13:10:27.782+0000] {taskinstance.py:2648} INFO - Exporting env vars: AIRFLOW_CTX_DAG_OWNER='test' AIRFLOW_CTX_DAG_ID='dag_with_postgres_operator_v03' AIRFLOW_CTX_TASK_ID='create_postgres_table' AIRFLOW_CTX_EXECUTION_DATE='2021-12-26T00:00:00+00:00' AIRFLOW_CTX_TRY_NUMBER='3' AIRFLOW_CTX_DAG_RUN_ID='scheduled__2021-12-26T00:00:00+00:00'
[2024-05-27T13:10:27.783+0000] {taskinstance.py:430} INFO - ::endgroup::
[2024-05-27T13:10:27.799+0000] {sql.py:276} INFO - Executing: 
            create table if not exists dag_runs (
                dt date,
                dag_id character varying,
                primary key (dt, dag_id)
            )
        
[2024-05-27T13:10:27.810+0000] {base.py:84} INFO - Using connection ID 'postgres_localhost' for task execution.
[2024-05-27T13:10:27.820+0000] {base.py:84} INFO - Using connection ID 'postgres_localhost' for task execution.
[2024-05-27T13:10:27.822+0000] {taskinstance.py:441} INFO - ::group::Post task execution logs
[2024-05-27T13:10:27.823+0000] {taskinstance.py:2905} ERROR - Task failed with exception
Traceback (most recent call last):
  File "/home/airflow/.local/lib/python3.12/site-packages/airflow/models/taskinstance.py", line 465, in _execute_task
    result = _execute_callable(context=context, **execute_callable_kwargs)
             ^^^^^^^^^^^^^^^^^^^^^^^^^^^^^^^^^^^^^^^^^^^^^^^^^^^^^^^^^^^^^
  File "/home/airflow/.local/lib/python3.12/site-packages/airflow/models/taskinstance.py", line 432, in _execute_callable
    return execute_callable(context=context, **execute_callable_kwargs)
           ^^^^^^^^^^^^^^^^^^^^^^^^^^^^^^^^^^^^^^^^^^^^^^^^^^^^^^^^^^^^
  File "/home/airflow/.local/lib/python3.12/site-packages/airflow/models/baseoperator.py", line 400, in wrapper
    return func(self, *args, **kwargs)
           ^^^^^^^^^^^^^^^^^^^^^^^^^^^
  File "/home/airflow/.local/lib/python3.12/site-packages/airflow/providers/common/sql/operators/sql.py", line 282, in execute
    output = hook.run(
             ^^^^^^^^^
  File "/home/airflow/.local/lib/python3.12/site-packages/airflow/providers/common/sql/hooks/sql.py", line 411, in run
    with closing(self.get_conn()) as conn:
                 ^^^^^^^^^^^^^^^
  File "/home/airflow/.local/lib/python3.12/site-packages/airflow/providers/postgres/hooks/postgres.py", line 161, in get_conn
    self.conn = psycopg2.connect(**conn_args)
                ^^^^^^^^^^^^^^^^^^^^^^^^^^^^^
  File "/home/airflow/.local/lib/python3.12/site-packages/psycopg2/__init__.py", line 122, in connect
    conn = _connect(dsn, connection_factory=connection_factory, **kwasync)
           ^^^^^^^^^^^^^^^^^^^^^^^^^^^^^^^^^^^^^^^^^^^^^^^^^^^^^^^^^^^^^^^
psycopg2.OperationalError: connection to server at "localhost" (127.0.0.1), port 543 failed: Connection refused
	Is the server running on that host and accepting TCP/IP connections?
connection to server at "localhost" (::1), port 543 failed: Cannot assign requested address
	Is the server running on that host and accepting TCP/IP connections?

[2024-05-27T13:10:27.833+0000] {taskinstance.py:1206} INFO - Marking task as UP_FOR_RETRY. dag_id=dag_with_postgres_operator_v03, task_id=create_postgres_table, run_id=scheduled__2021-12-26T00:00:00+00:00, execution_date=20211226T000000, start_date=20240527T131027, end_date=20240527T131027
[2024-05-27T13:10:27.848+0000] {standard_task_runner.py:110} ERROR - Failed to execute job 72 for task create_postgres_table (connection to server at "localhost" (127.0.0.1), port 543 failed: Connection refused
	Is the server running on that host and accepting TCP/IP connections?
connection to server at "localhost" (::1), port 543 failed: Cannot assign requested address
	Is the server running on that host and accepting TCP/IP connections?
; 252)
[2024-05-27T13:10:27.860+0000] {local_task_job_runner.py:240} INFO - Task exited with return code 1
[2024-05-27T13:10:27.870+0000] {local_task_job_runner.py:222} INFO - ::endgroup::
[2024-05-27T13:27:21.393+0000] {local_task_job_runner.py:120} INFO - ::group::Pre task execution logs
[2024-05-27T13:27:21.420+0000] {taskinstance.py:2076} INFO - Dependencies all met for dep_context=non-requeueable deps ti=<TaskInstance: dag_with_postgres_operator_v03.create_postgres_table scheduled__2021-12-26T00:00:00+00:00 [queued]>
[2024-05-27T13:27:21.430+0000] {taskinstance.py:2076} INFO - Dependencies all met for dep_context=requeueable deps ti=<TaskInstance: dag_with_postgres_operator_v03.create_postgres_table scheduled__2021-12-26T00:00:00+00:00 [queued]>
[2024-05-27T13:27:21.430+0000] {taskinstance.py:2306} INFO - Starting attempt 3 of 6
[2024-05-27T13:27:21.444+0000] {taskinstance.py:2330} INFO - Executing <Task(PostgresOperator): create_postgres_table> on 2021-12-26 00:00:00+00:00
[2024-05-27T13:27:21.453+0000] {standard_task_runner.py:90} INFO - Running: ['***', 'tasks', 'run', 'dag_with_postgres_operator_v03', 'create_postgres_table', 'scheduled__2021-12-26T00:00:00+00:00', '--job-id', '116', '--raw', '--subdir', 'DAGS_FOLDER/dag_with_postgres_operator.py', '--cfg-path', '/tmp/tmp1zqvujyv']
[2024-05-27T13:27:21.452+0000] {warnings.py:110} WARNING - /home/***/.local/lib/python3.12/site-packages/***/task/task_runner/standard_task_runner.py:61: DeprecationWarning: This process (pid=284) is multi-threaded, use of fork() may lead to deadlocks in the child.
  pid = os.fork()

[2024-05-27T13:27:21.455+0000] {standard_task_runner.py:91} INFO - Job 116: Subtask create_postgres_table
[2024-05-27T13:27:21.456+0000] {standard_task_runner.py:63} INFO - Started process 287 to run task
[2024-05-27T13:27:21.515+0000] {task_command.py:426} INFO - Running <TaskInstance: dag_with_postgres_operator_v03.create_postgres_table scheduled__2021-12-26T00:00:00+00:00 [running]> on host 2f91d40c74f3
[2024-05-27T13:27:21.619+0000] {taskinstance.py:2648} INFO - Exporting env vars: AIRFLOW_CTX_DAG_OWNER='test' AIRFLOW_CTX_DAG_ID='dag_with_postgres_operator_v03' AIRFLOW_CTX_TASK_ID='create_postgres_table' AIRFLOW_CTX_EXECUTION_DATE='2021-12-26T00:00:00+00:00' AIRFLOW_CTX_TRY_NUMBER='3' AIRFLOW_CTX_DAG_RUN_ID='scheduled__2021-12-26T00:00:00+00:00'
[2024-05-27T13:27:21.621+0000] {taskinstance.py:430} INFO - ::endgroup::
[2024-05-27T13:27:21.640+0000] {sql.py:276} INFO - Executing: 
            create table if not exists dag_runs (
                dt date,
                dag_id character varying,
                primary key (dt, dag_id)
            )
        
[2024-05-27T13:27:21.649+0000] {base.py:84} INFO - Using connection ID 'postgres_localhost' for task execution.
[2024-05-27T13:27:21.659+0000] {base.py:84} INFO - Using connection ID 'postgres_localhost' for task execution.
[2024-05-27T13:27:23.716+0000] {taskinstance.py:441} INFO - ::group::Post task execution logs
[2024-05-27T13:27:23.717+0000] {taskinstance.py:2905} ERROR - Task failed with exception
Traceback (most recent call last):
  File "/home/airflow/.local/lib/python3.12/site-packages/airflow/models/taskinstance.py", line 465, in _execute_task
    result = _execute_callable(context=context, **execute_callable_kwargs)
             ^^^^^^^^^^^^^^^^^^^^^^^^^^^^^^^^^^^^^^^^^^^^^^^^^^^^^^^^^^^^^
  File "/home/airflow/.local/lib/python3.12/site-packages/airflow/models/taskinstance.py", line 432, in _execute_callable
    return execute_callable(context=context, **execute_callable_kwargs)
           ^^^^^^^^^^^^^^^^^^^^^^^^^^^^^^^^^^^^^^^^^^^^^^^^^^^^^^^^^^^^
  File "/home/airflow/.local/lib/python3.12/site-packages/airflow/models/baseoperator.py", line 400, in wrapper
    return func(self, *args, **kwargs)
           ^^^^^^^^^^^^^^^^^^^^^^^^^^^
  File "/home/airflow/.local/lib/python3.12/site-packages/airflow/providers/common/sql/operators/sql.py", line 282, in execute
    output = hook.run(
             ^^^^^^^^^
  File "/home/airflow/.local/lib/python3.12/site-packages/airflow/providers/common/sql/hooks/sql.py", line 411, in run
    with closing(self.get_conn()) as conn:
                 ^^^^^^^^^^^^^^^
  File "/home/airflow/.local/lib/python3.12/site-packages/airflow/providers/postgres/hooks/postgres.py", line 161, in get_conn
    self.conn = psycopg2.connect(**conn_args)
                ^^^^^^^^^^^^^^^^^^^^^^^^^^^^^
  File "/home/airflow/.local/lib/python3.12/site-packages/psycopg2/__init__.py", line 122, in connect
    conn = _connect(dsn, connection_factory=connection_factory, **kwasync)
           ^^^^^^^^^^^^^^^^^^^^^^^^^^^^^^^^^^^^^^^^^^^^^^^^^^^^^^^^^^^^^^^
psycopg2.OperationalError: connection to server at "host.docker.internal" (192.168.65.254), port 543 failed: Connection refused
	Is the server running on that host and accepting TCP/IP connections?

[2024-05-27T13:27:23.731+0000] {taskinstance.py:1206} INFO - Marking task as UP_FOR_RETRY. dag_id=dag_with_postgres_operator_v03, task_id=create_postgres_table, run_id=scheduled__2021-12-26T00:00:00+00:00, execution_date=20211226T000000, start_date=20240527T132721, end_date=20240527T132723
[2024-05-27T13:27:23.756+0000] {standard_task_runner.py:110} ERROR - Failed to execute job 116 for task create_postgres_table (connection to server at "host.docker.internal" (192.168.65.254), port 543 failed: Connection refused
	Is the server running on that host and accepting TCP/IP connections?
; 287)
[2024-05-27T13:27:23.799+0000] {local_task_job_runner.py:240} INFO - Task exited with return code 1
[2024-05-27T13:27:23.814+0000] {taskinstance.py:3498} INFO - 0 downstream tasks scheduled from follow-on schedule check
[2024-05-27T13:27:23.818+0000] {local_task_job_runner.py:222} INFO - ::endgroup::
