[2024-05-27T11:55:42.105+0000] {local_task_job_runner.py:120} INFO - ::group::Pre task execution logs
[2024-05-27T11:55:42.129+0000] {taskinstance.py:2076} INFO - Dependencies all met for dep_context=non-requeueable deps ti=<TaskInstance: dag_with_postgres_operator_v03.create_postgres_table scheduled__2021-12-23T00:00:00+00:00 [queued]>
[2024-05-27T11:55:42.139+0000] {taskinstance.py:2076} INFO - Dependencies all met for dep_context=requeueable deps ti=<TaskInstance: dag_with_postgres_operator_v03.create_postgres_table scheduled__2021-12-23T00:00:00+00:00 [queued]>
[2024-05-27T11:55:42.140+0000] {taskinstance.py:2306} INFO - Starting attempt 1 of 6
[2024-05-27T11:55:42.159+0000] {taskinstance.py:2330} INFO - Executing <Task(PostgresOperator): create_postgres_table> on 2021-12-23 00:00:00+00:00
[2024-05-27T11:55:42.165+0000] {warnings.py:110} WARNING - /home/***/.local/lib/python3.12/site-packages/***/task/task_runner/standard_task_runner.py:61: DeprecationWarning: This process (pid=75) is multi-threaded, use of fork() may lead to deadlocks in the child.
  pid = os.fork()

[2024-05-27T11:55:42.167+0000] {standard_task_runner.py:63} INFO - Started process 82 to run task
[2024-05-27T11:55:42.167+0000] {standard_task_runner.py:90} INFO - Running: ['***', 'tasks', 'run', 'dag_with_postgres_operator_v03', 'create_postgres_table', 'scheduled__2021-12-23T00:00:00+00:00', '--job-id', '30', '--raw', '--subdir', 'DAGS_FOLDER/dag_with_postgres_operator.py', '--cfg-path', '/tmp/tmpet34vuc7']
[2024-05-27T11:55:42.169+0000] {standard_task_runner.py:91} INFO - Job 30: Subtask create_postgres_table
[2024-05-27T11:55:42.218+0000] {task_command.py:426} INFO - Running <TaskInstance: dag_with_postgres_operator_v03.create_postgres_table scheduled__2021-12-23T00:00:00+00:00 [running]> on host bce46d08f6f0
[2024-05-27T11:55:42.302+0000] {taskinstance.py:2648} INFO - Exporting env vars: AIRFLOW_CTX_DAG_OWNER='test' AIRFLOW_CTX_DAG_ID='dag_with_postgres_operator_v03' AIRFLOW_CTX_TASK_ID='create_postgres_table' AIRFLOW_CTX_EXECUTION_DATE='2021-12-23T00:00:00+00:00' AIRFLOW_CTX_TRY_NUMBER='1' AIRFLOW_CTX_DAG_RUN_ID='scheduled__2021-12-23T00:00:00+00:00'
[2024-05-27T11:55:42.303+0000] {taskinstance.py:430} INFO - ::endgroup::
[2024-05-27T11:55:42.315+0000] {sql.py:276} INFO - Executing: 
            create table if not exists dag_runs (
                dt date,
                dag_id character varying,
                primary key (dt, dag_id)
            )
        
[2024-05-27T11:55:42.322+0000] {base.py:84} INFO - Using connection ID 'postgres_localhost' for task execution.
[2024-05-27T11:55:42.333+0000] {base.py:84} INFO - Using connection ID 'postgres_localhost' for task execution.
[2024-05-27T11:55:42.334+0000] {taskinstance.py:441} INFO - ::group::Post task execution logs
[2024-05-27T11:55:42.335+0000] {taskinstance.py:2905} ERROR - Task failed with exception
Traceback (most recent call last):
  File "/home/airflow/.local/lib/python3.12/site-packages/airflow/models/taskinstance.py", line 465, in _execute_task
    result = _execute_callable(context=context, **execute_callable_kwargs)
             ^^^^^^^^^^^^^^^^^^^^^^^^^^^^^^^^^^^^^^^^^^^^^^^^^^^^^^^^^^^^^
  File "/home/airflow/.local/lib/python3.12/site-packages/airflow/models/taskinstance.py", line 432, in _execute_callable
    return execute_callable(context=context, **execute_callable_kwargs)
           ^^^^^^^^^^^^^^^^^^^^^^^^^^^^^^^^^^^^^^^^^^^^^^^^^^^^^^^^^^^^
  File "/home/airflow/.local/lib/python3.12/site-packages/airflow/models/baseoperator.py", line 400, in wrapper
    return func(self, *args, **kwargs)
           ^^^^^^^^^^^^^^^^^^^^^^^^^^^
  File "/home/airflow/.local/lib/python3.12/site-packages/airflow/providers/common/sql/operators/sql.py", line 282, in execute
    output = hook.run(
             ^^^^^^^^^
  File "/home/airflow/.local/lib/python3.12/site-packages/airflow/providers/common/sql/hooks/sql.py", line 411, in run
    with closing(self.get_conn()) as conn:
                 ^^^^^^^^^^^^^^^
  File "/home/airflow/.local/lib/python3.12/site-packages/airflow/providers/postgres/hooks/postgres.py", line 161, in get_conn
    self.conn = psycopg2.connect(**conn_args)
                ^^^^^^^^^^^^^^^^^^^^^^^^^^^^^
  File "/home/airflow/.local/lib/python3.12/site-packages/psycopg2/__init__.py", line 122, in connect
    conn = _connect(dsn, connection_factory=connection_factory, **kwasync)
           ^^^^^^^^^^^^^^^^^^^^^^^^^^^^^^^^^^^^^^^^^^^^^^^^^^^^^^^^^^^^^^^
psycopg2.OperationalError: connection to server at "localhost" (127.0.0.1), port 543 failed: Connection refused
	Is the server running on that host and accepting TCP/IP connections?
connection to server at "localhost" (::1), port 543 failed: Cannot assign requested address
	Is the server running on that host and accepting TCP/IP connections?

[2024-05-27T11:55:42.344+0000] {taskinstance.py:1206} INFO - Marking task as UP_FOR_RETRY. dag_id=dag_with_postgres_operator_v03, task_id=create_postgres_table, run_id=scheduled__2021-12-23T00:00:00+00:00, execution_date=20211223T000000, start_date=20240527T115542, end_date=20240527T115542
[2024-05-27T11:55:42.432+0000] {standard_task_runner.py:110} ERROR - Failed to execute job 30 for task create_postgres_table (connection to server at "localhost" (127.0.0.1), port 543 failed: Connection refused
	Is the server running on that host and accepting TCP/IP connections?
connection to server at "localhost" (::1), port 543 failed: Cannot assign requested address
	Is the server running on that host and accepting TCP/IP connections?
; 82)
[2024-05-27T11:55:42.462+0000] {local_task_job_runner.py:240} INFO - Task exited with return code 1
[2024-05-27T11:55:42.472+0000] {warnings.py:110} WARNING - /home/***/.local/lib/python3.12/site-packages/***/models/baseoperator.py:1296: AirflowProviderDeprecationWarning: Call to deprecated class PostgresOperator. (Please use `***.providers.common.sql.operators.sql.SQLExecuteQueryOperator`.Also, you can provide `hook_params={'schema': <database>}`.)
  result = cls.__new__(cls)

[2024-05-27T11:55:42.486+0000] {taskinstance.py:3498} INFO - 0 downstream tasks scheduled from follow-on schedule check
[2024-05-27T11:55:42.490+0000] {local_task_job_runner.py:222} INFO - ::endgroup::
[2024-05-27T13:17:18.975+0000] {local_task_job_runner.py:120} INFO - ::group::Pre task execution logs
[2024-05-27T13:17:19.003+0000] {taskinstance.py:2076} INFO - Dependencies all met for dep_context=non-requeueable deps ti=<TaskInstance: dag_with_postgres_operator_v03.create_postgres_table scheduled__2021-12-23T00:00:00+00:00 [queued]>
[2024-05-27T13:17:19.012+0000] {taskinstance.py:2076} INFO - Dependencies all met for dep_context=requeueable deps ti=<TaskInstance: dag_with_postgres_operator_v03.create_postgres_table scheduled__2021-12-23T00:00:00+00:00 [queued]>
[2024-05-27T13:17:19.013+0000] {taskinstance.py:2306} INFO - Starting attempt 1 of 6
[2024-05-27T13:17:19.064+0000] {taskinstance.py:2330} INFO - Executing <Task(PostgresOperator): create_postgres_table> on 2021-12-23 00:00:00+00:00
[2024-05-27T13:17:19.072+0000] {warnings.py:110} WARNING - /home/***/.local/lib/python3.12/site-packages/***/task/task_runner/standard_task_runner.py:61: DeprecationWarning: This process (pid=79) is multi-threaded, use of fork() may lead to deadlocks in the child.
  pid = os.fork()

[2024-05-27T13:17:19.074+0000] {standard_task_runner.py:63} INFO - Started process 87 to run task
[2024-05-27T13:17:19.073+0000] {standard_task_runner.py:90} INFO - Running: ['***', 'tasks', 'run', 'dag_with_postgres_operator_v03', 'create_postgres_table', 'scheduled__2021-12-23T00:00:00+00:00', '--job-id', '80', '--raw', '--subdir', 'DAGS_FOLDER/dag_with_postgres_operator.py', '--cfg-path', '/tmp/tmp35s805b3']
[2024-05-27T13:17:19.075+0000] {standard_task_runner.py:91} INFO - Job 80: Subtask create_postgres_table
[2024-05-27T13:17:19.137+0000] {task_command.py:426} INFO - Running <TaskInstance: dag_with_postgres_operator_v03.create_postgres_table scheduled__2021-12-23T00:00:00+00:00 [running]> on host 2f91d40c74f3
[2024-05-27T13:17:19.261+0000] {taskinstance.py:2648} INFO - Exporting env vars: AIRFLOW_CTX_DAG_OWNER='test' AIRFLOW_CTX_DAG_ID='dag_with_postgres_operator_v03' AIRFLOW_CTX_TASK_ID='create_postgres_table' AIRFLOW_CTX_EXECUTION_DATE='2021-12-23T00:00:00+00:00' AIRFLOW_CTX_TRY_NUMBER='1' AIRFLOW_CTX_DAG_RUN_ID='scheduled__2021-12-23T00:00:00+00:00'
[2024-05-27T13:17:19.263+0000] {taskinstance.py:430} INFO - ::endgroup::
[2024-05-27T13:17:19.282+0000] {sql.py:276} INFO - Executing: 
            create table if not exists dag_runs (
                dt date,
                dag_id character varying,
                primary key (dt, dag_id)
            )
        
[2024-05-27T13:17:19.294+0000] {base.py:84} INFO - Using connection ID 'postgres_localhost' for task execution.
[2024-05-27T13:17:19.306+0000] {base.py:84} INFO - Using connection ID 'postgres_localhost' for task execution.
[2024-05-27T13:17:19.308+0000] {taskinstance.py:441} INFO - ::group::Post task execution logs
[2024-05-27T13:17:19.308+0000] {taskinstance.py:2905} ERROR - Task failed with exception
Traceback (most recent call last):
  File "/home/airflow/.local/lib/python3.12/site-packages/airflow/models/taskinstance.py", line 465, in _execute_task
    result = _execute_callable(context=context, **execute_callable_kwargs)
             ^^^^^^^^^^^^^^^^^^^^^^^^^^^^^^^^^^^^^^^^^^^^^^^^^^^^^^^^^^^^^
  File "/home/airflow/.local/lib/python3.12/site-packages/airflow/models/taskinstance.py", line 432, in _execute_callable
    return execute_callable(context=context, **execute_callable_kwargs)
           ^^^^^^^^^^^^^^^^^^^^^^^^^^^^^^^^^^^^^^^^^^^^^^^^^^^^^^^^^^^^
  File "/home/airflow/.local/lib/python3.12/site-packages/airflow/models/baseoperator.py", line 400, in wrapper
    return func(self, *args, **kwargs)
           ^^^^^^^^^^^^^^^^^^^^^^^^^^^
  File "/home/airflow/.local/lib/python3.12/site-packages/airflow/providers/common/sql/operators/sql.py", line 282, in execute
    output = hook.run(
             ^^^^^^^^^
  File "/home/airflow/.local/lib/python3.12/site-packages/airflow/providers/common/sql/hooks/sql.py", line 411, in run
    with closing(self.get_conn()) as conn:
                 ^^^^^^^^^^^^^^^
  File "/home/airflow/.local/lib/python3.12/site-packages/airflow/providers/postgres/hooks/postgres.py", line 161, in get_conn
    self.conn = psycopg2.connect(**conn_args)
                ^^^^^^^^^^^^^^^^^^^^^^^^^^^^^
  File "/home/airflow/.local/lib/python3.12/site-packages/psycopg2/__init__.py", line 122, in connect
    conn = _connect(dsn, connection_factory=connection_factory, **kwasync)
           ^^^^^^^^^^^^^^^^^^^^^^^^^^^^^^^^^^^^^^^^^^^^^^^^^^^^^^^^^^^^^^^
psycopg2.OperationalError: connection to server at "localhost" (127.0.0.1), port 543 failed: Connection refused
	Is the server running on that host and accepting TCP/IP connections?
connection to server at "localhost" (::1), port 543 failed: Cannot assign requested address
	Is the server running on that host and accepting TCP/IP connections?

[2024-05-27T13:17:19.322+0000] {taskinstance.py:1206} INFO - Marking task as UP_FOR_RETRY. dag_id=dag_with_postgres_operator_v03, task_id=create_postgres_table, run_id=scheduled__2021-12-23T00:00:00+00:00, execution_date=20211223T000000, start_date=20240527T131719, end_date=20240527T131719
[2024-05-27T13:17:19.340+0000] {standard_task_runner.py:110} ERROR - Failed to execute job 80 for task create_postgres_table (connection to server at "localhost" (127.0.0.1), port 543 failed: Connection refused
	Is the server running on that host and accepting TCP/IP connections?
connection to server at "localhost" (::1), port 543 failed: Cannot assign requested address
	Is the server running on that host and accepting TCP/IP connections?
; 87)
[2024-05-27T13:17:19.369+0000] {local_task_job_runner.py:240} INFO - Task exited with return code 1
[2024-05-27T13:17:19.379+0000] {local_task_job_runner.py:222} INFO - ::endgroup::
