[2024-05-27T13:10:25.960+0000] {local_task_job_runner.py:120} INFO - ::group::Pre task execution logs
[2024-05-27T13:10:26.034+0000] {taskinstance.py:2076} INFO - Dependencies all met for dep_context=non-requeueable deps ti=<TaskInstance: dag_with_postgres_operator_v03.create_postgres_table scheduled__2021-12-27T00:00:00+00:00 [queued]>
[2024-05-27T13:10:26.145+0000] {taskinstance.py:2076} INFO - Dependencies all met for dep_context=requeueable deps ti=<TaskInstance: dag_with_postgres_operator_v03.create_postgres_table scheduled__2021-12-27T00:00:00+00:00 [queued]>
[2024-05-27T13:10:26.146+0000] {taskinstance.py:2306} INFO - Starting attempt 3 of 6
[2024-05-27T13:10:26.227+0000] {taskinstance.py:2330} INFO - Executing <Task(PostgresOperator): create_postgres_table> on 2021-12-27 00:00:00+00:00
[2024-05-27T13:10:26.264+0000] {standard_task_runner.py:90} INFO - Running: ['***', 'tasks', 'run', 'dag_with_postgres_operator_v03', 'create_postgres_table', 'scheduled__2021-12-27T00:00:00+00:00', '--job-id', '57', '--raw', '--subdir', 'DAGS_FOLDER/dag_with_postgres_operator.py', '--cfg-path', '/tmp/tmpa0a88c9z']
[2024-05-27T13:10:26.268+0000] {standard_task_runner.py:91} INFO - Job 57: Subtask create_postgres_table
[2024-05-27T13:10:26.277+0000] {warnings.py:110} WARNING - /home/***/.local/lib/python3.12/site-packages/***/task/task_runner/standard_task_runner.py:61: DeprecationWarning: This process (pid=228) is multi-threaded, use of fork() may lead to deadlocks in the child.
  pid = os.fork()

[2024-05-27T13:10:26.281+0000] {standard_task_runner.py:63} INFO - Started process 238 to run task
[2024-05-27T13:10:26.937+0000] {task_command.py:426} INFO - Running <TaskInstance: dag_with_postgres_operator_v03.create_postgres_table scheduled__2021-12-27T00:00:00+00:00 [running]> on host bce46d08f6f0
[2024-05-27T13:10:27.276+0000] {taskinstance.py:2648} INFO - Exporting env vars: AIRFLOW_CTX_DAG_OWNER='test' AIRFLOW_CTX_DAG_ID='dag_with_postgres_operator_v03' AIRFLOW_CTX_TASK_ID='create_postgres_table' AIRFLOW_CTX_EXECUTION_DATE='2021-12-27T00:00:00+00:00' AIRFLOW_CTX_TRY_NUMBER='3' AIRFLOW_CTX_DAG_RUN_ID='scheduled__2021-12-27T00:00:00+00:00'
[2024-05-27T13:10:27.282+0000] {taskinstance.py:430} INFO - ::endgroup::
[2024-05-27T13:10:27.323+0000] {sql.py:276} INFO - Executing: 
            create table if not exists dag_runs (
                dt date,
                dag_id character varying,
                primary key (dt, dag_id)
            )
        
[2024-05-27T13:10:27.373+0000] {base.py:84} INFO - Using connection ID 'postgres_localhost' for task execution.
[2024-05-27T13:10:27.409+0000] {base.py:84} INFO - Using connection ID 'postgres_localhost' for task execution.
[2024-05-27T13:10:27.417+0000] {taskinstance.py:441} INFO - ::group::Post task execution logs
[2024-05-27T13:10:27.419+0000] {taskinstance.py:2905} ERROR - Task failed with exception
Traceback (most recent call last):
  File "/home/airflow/.local/lib/python3.12/site-packages/airflow/models/taskinstance.py", line 465, in _execute_task
    result = _execute_callable(context=context, **execute_callable_kwargs)
             ^^^^^^^^^^^^^^^^^^^^^^^^^^^^^^^^^^^^^^^^^^^^^^^^^^^^^^^^^^^^^
  File "/home/airflow/.local/lib/python3.12/site-packages/airflow/models/taskinstance.py", line 432, in _execute_callable
    return execute_callable(context=context, **execute_callable_kwargs)
           ^^^^^^^^^^^^^^^^^^^^^^^^^^^^^^^^^^^^^^^^^^^^^^^^^^^^^^^^^^^^
  File "/home/airflow/.local/lib/python3.12/site-packages/airflow/models/baseoperator.py", line 400, in wrapper
    return func(self, *args, **kwargs)
           ^^^^^^^^^^^^^^^^^^^^^^^^^^^
  File "/home/airflow/.local/lib/python3.12/site-packages/airflow/providers/common/sql/operators/sql.py", line 282, in execute
    output = hook.run(
             ^^^^^^^^^
  File "/home/airflow/.local/lib/python3.12/site-packages/airflow/providers/common/sql/hooks/sql.py", line 411, in run
    with closing(self.get_conn()) as conn:
                 ^^^^^^^^^^^^^^^
  File "/home/airflow/.local/lib/python3.12/site-packages/airflow/providers/postgres/hooks/postgres.py", line 161, in get_conn
    self.conn = psycopg2.connect(**conn_args)
                ^^^^^^^^^^^^^^^^^^^^^^^^^^^^^
  File "/home/airflow/.local/lib/python3.12/site-packages/psycopg2/__init__.py", line 122, in connect
    conn = _connect(dsn, connection_factory=connection_factory, **kwasync)
           ^^^^^^^^^^^^^^^^^^^^^^^^^^^^^^^^^^^^^^^^^^^^^^^^^^^^^^^^^^^^^^^
psycopg2.OperationalError: connection to server at "localhost" (127.0.0.1), port 543 failed: Connection refused
	Is the server running on that host and accepting TCP/IP connections?
connection to server at "localhost" (::1), port 543 failed: Cannot assign requested address
	Is the server running on that host and accepting TCP/IP connections?

[2024-05-27T13:10:27.452+0000] {taskinstance.py:1206} INFO - Marking task as UP_FOR_RETRY. dag_id=dag_with_postgres_operator_v03, task_id=create_postgres_table, run_id=scheduled__2021-12-27T00:00:00+00:00, execution_date=20211227T000000, start_date=20240527T131026, end_date=20240527T131027
[2024-05-27T13:10:27.483+0000] {standard_task_runner.py:110} ERROR - Failed to execute job 57 for task create_postgres_table (connection to server at "localhost" (127.0.0.1), port 543 failed: Connection refused
	Is the server running on that host and accepting TCP/IP connections?
connection to server at "localhost" (::1), port 543 failed: Cannot assign requested address
	Is the server running on that host and accepting TCP/IP connections?
; 238)
[2024-05-27T13:10:27.497+0000] {local_task_job_runner.py:240} INFO - Task exited with return code 1
[2024-05-27T13:10:27.521+0000] {taskinstance.py:3498} INFO - 0 downstream tasks scheduled from follow-on schedule check
[2024-05-27T13:10:27.529+0000] {local_task_job_runner.py:222} INFO - ::endgroup::
[2024-05-27T13:27:21.423+0000] {local_task_job_runner.py:120} INFO - ::group::Pre task execution logs
[2024-05-27T13:27:21.450+0000] {taskinstance.py:2076} INFO - Dependencies all met for dep_context=non-requeueable deps ti=<TaskInstance: dag_with_postgres_operator_v03.create_postgres_table scheduled__2021-12-27T00:00:00+00:00 [queued]>
[2024-05-27T13:27:21.458+0000] {taskinstance.py:2076} INFO - Dependencies all met for dep_context=requeueable deps ti=<TaskInstance: dag_with_postgres_operator_v03.create_postgres_table scheduled__2021-12-27T00:00:00+00:00 [queued]>
[2024-05-27T13:27:21.459+0000] {taskinstance.py:2306} INFO - Starting attempt 3 of 6
[2024-05-27T13:27:21.474+0000] {taskinstance.py:2330} INFO - Executing <Task(PostgresOperator): create_postgres_table> on 2021-12-27 00:00:00+00:00
[2024-05-27T13:27:21.480+0000] {warnings.py:110} WARNING - /home/***/.local/lib/python3.12/site-packages/***/task/task_runner/standard_task_runner.py:61: DeprecationWarning: This process (pid=285) is multi-threaded, use of fork() may lead to deadlocks in the child.
  pid = os.fork()

[2024-05-27T13:27:21.481+0000] {standard_task_runner.py:90} INFO - Running: ['***', 'tasks', 'run', 'dag_with_postgres_operator_v03', 'create_postgres_table', 'scheduled__2021-12-27T00:00:00+00:00', '--job-id', '117', '--raw', '--subdir', 'DAGS_FOLDER/dag_with_postgres_operator.py', '--cfg-path', '/tmp/tmpjgghemgm']
[2024-05-27T13:27:21.484+0000] {standard_task_runner.py:63} INFO - Started process 288 to run task
[2024-05-27T13:27:21.484+0000] {standard_task_runner.py:91} INFO - Job 117: Subtask create_postgres_table
[2024-05-27T13:27:21.562+0000] {task_command.py:426} INFO - Running <TaskInstance: dag_with_postgres_operator_v03.create_postgres_table scheduled__2021-12-27T00:00:00+00:00 [running]> on host 2f91d40c74f3
[2024-05-27T13:27:21.666+0000] {taskinstance.py:2648} INFO - Exporting env vars: AIRFLOW_CTX_DAG_OWNER='test' AIRFLOW_CTX_DAG_ID='dag_with_postgres_operator_v03' AIRFLOW_CTX_TASK_ID='create_postgres_table' AIRFLOW_CTX_EXECUTION_DATE='2021-12-27T00:00:00+00:00' AIRFLOW_CTX_TRY_NUMBER='3' AIRFLOW_CTX_DAG_RUN_ID='scheduled__2021-12-27T00:00:00+00:00'
[2024-05-27T13:27:21.668+0000] {taskinstance.py:430} INFO - ::endgroup::
[2024-05-27T13:27:21.690+0000] {sql.py:276} INFO - Executing: 
            create table if not exists dag_runs (
                dt date,
                dag_id character varying,
                primary key (dt, dag_id)
            )
        
[2024-05-27T13:27:21.702+0000] {base.py:84} INFO - Using connection ID 'postgres_localhost' for task execution.
[2024-05-27T13:27:21.716+0000] {base.py:84} INFO - Using connection ID 'postgres_localhost' for task execution.
[2024-05-27T13:27:23.762+0000] {taskinstance.py:441} INFO - ::group::Post task execution logs
[2024-05-27T13:27:23.763+0000] {taskinstance.py:2905} ERROR - Task failed with exception
Traceback (most recent call last):
  File "/home/airflow/.local/lib/python3.12/site-packages/airflow/models/taskinstance.py", line 465, in _execute_task
    result = _execute_callable(context=context, **execute_callable_kwargs)
             ^^^^^^^^^^^^^^^^^^^^^^^^^^^^^^^^^^^^^^^^^^^^^^^^^^^^^^^^^^^^^
  File "/home/airflow/.local/lib/python3.12/site-packages/airflow/models/taskinstance.py", line 432, in _execute_callable
    return execute_callable(context=context, **execute_callable_kwargs)
           ^^^^^^^^^^^^^^^^^^^^^^^^^^^^^^^^^^^^^^^^^^^^^^^^^^^^^^^^^^^^
  File "/home/airflow/.local/lib/python3.12/site-packages/airflow/models/baseoperator.py", line 400, in wrapper
    return func(self, *args, **kwargs)
           ^^^^^^^^^^^^^^^^^^^^^^^^^^^
  File "/home/airflow/.local/lib/python3.12/site-packages/airflow/providers/common/sql/operators/sql.py", line 282, in execute
    output = hook.run(
             ^^^^^^^^^
  File "/home/airflow/.local/lib/python3.12/site-packages/airflow/providers/common/sql/hooks/sql.py", line 411, in run
    with closing(self.get_conn()) as conn:
                 ^^^^^^^^^^^^^^^
  File "/home/airflow/.local/lib/python3.12/site-packages/airflow/providers/postgres/hooks/postgres.py", line 161, in get_conn
    self.conn = psycopg2.connect(**conn_args)
                ^^^^^^^^^^^^^^^^^^^^^^^^^^^^^
  File "/home/airflow/.local/lib/python3.12/site-packages/psycopg2/__init__.py", line 122, in connect
    conn = _connect(dsn, connection_factory=connection_factory, **kwasync)
           ^^^^^^^^^^^^^^^^^^^^^^^^^^^^^^^^^^^^^^^^^^^^^^^^^^^^^^^^^^^^^^^
psycopg2.OperationalError: connection to server at "host.docker.internal" (192.168.65.254), port 543 failed: Connection refused
	Is the server running on that host and accepting TCP/IP connections?

[2024-05-27T13:27:23.772+0000] {taskinstance.py:1206} INFO - Marking task as UP_FOR_RETRY. dag_id=dag_with_postgres_operator_v03, task_id=create_postgres_table, run_id=scheduled__2021-12-27T00:00:00+00:00, execution_date=20211227T000000, start_date=20240527T132721, end_date=20240527T132723
[2024-05-27T13:27:23.859+0000] {standard_task_runner.py:110} ERROR - Failed to execute job 117 for task create_postgres_table (connection to server at "host.docker.internal" (192.168.65.254), port 543 failed: Connection refused
	Is the server running on that host and accepting TCP/IP connections?
; 288)
[2024-05-27T13:27:23.907+0000] {local_task_job_runner.py:240} INFO - Task exited with return code 1
[2024-05-27T13:27:23.923+0000] {taskinstance.py:3498} INFO - 0 downstream tasks scheduled from follow-on schedule check
[2024-05-27T13:27:23.926+0000] {local_task_job_runner.py:222} INFO - ::endgroup::
